<?xml version="1.0" ?>
<robot name="human_simplified">
  <!-- Base Link (Torso) -->
  <link name="torso">
    <visual>
      <geometry><box size="0.3 0.2 0.5"/></geometry>
      <origin xyz="0 0 0.25"/>
      <material name="grey"><color rgba="0.5 0.5 0.5 1"/></material>
    </visual>
    <collision>
      <geometry><box size="0.3 0.2 0.5"/></geometry>
      <origin xyz="0 0 0.25"/>
    </collision>
    <inertial> <mass value="10"/> <inertia ixx="1" ixy="0" ixz="0" iyy="1" iyz="0" izz="1"/> </inertial>
  </link>

  <!-- Placeholder for other links and joints (Shoulder, Elbow, Knee etc.) -->
  <!-- Example Right Arm -->
  <link name="upper_arm_r">
    <visual><geometry><cylinder radius="0.05" length="0.3"/></geometry><origin rpy="0 1.57 0" xyz="0 0 0.15"/><material name="blue"/></visual>
    <collision><geometry><cylinder radius="0.05" length="0.3"/></geometry><origin rpy="0 1.57 0" xyz="0 0 0.15"/></collision>
    <inertial> <mass value="1"/> <inertia ixx="0.1" ixy="0" ixz="0" iyy="0.1" iyz="0" izz="0.1"/> </inertial>
  </link>
  <joint name="shoulder_r" type="revolute">
    <parent link="torso"/><child link="upper_arm_r"/><origin xyz="0 -0.15 0.4"/><axis xyz="0 1 0"/><limit effort="100" lower="-3.14" upper="3.14" velocity="10"/>
  </joint>

  <link name="lower_arm_r">
      <visual><geometry><cylinder radius="0.04" length="0.25"/></geometry><origin rpy="0 1.57 0" xyz="0 0 0.125"/><material name="lightblue"/></visual>
      <collision><geometry><cylinder radius="0.04" length="0.25"/></geometry><origin rpy="0 1.57 0" xyz="0 0 0.125"/></collision>
      <inertial> <mass value="0.5"/> <inertia ixx="0.05" ixy="0" ixz="0" iyy="0.05" iyz="0" izz="0.05"/> </inertial>
  </link>
  <joint name="elbow_r" type="revolute">
      <parent link="upper_arm_r"/><child link="lower_arm_r"/><origin xyz="0 0 0.3"/><axis xyz="0 1 0"/><limit effort="100" lower="0" upper="2.8" velocity="10"/>
  </joint>

  <!-- Left Arm -->
  <link name="upper_arm_l">
    <visual><geometry><cylinder radius="0.05" length="0.3"/></geometry><origin rpy="0 1.57 0" xyz="0 0 0.15"/><material name="blue"/></visual>
    <collision><geometry><cylinder radius="0.05" length="0.3"/></geometry><origin rpy="0 1.57 0" xyz="0 0 0.15"/></collision>
    <inertial> <mass value="1"/> <inertia ixx="0.1" ixy="0" ixz="0" iyy="0.1" iyz="0" izz="0.1"/> </inertial>
  </link>
  <joint name="shoulder_l" type="revolute">
    <parent link="torso"/><child link="upper_arm_l"/><origin xyz="0 0.15 0.4"/><axis xyz="0 1 0"/><limit effort="100" lower="-3.14" upper="3.14" velocity="10"/>
  </joint>

  <link name="lower_arm_l">
      <visual><geometry><cylinder radius="0.04" length="0.25"/></geometry><origin rpy="0 1.57 0" xyz="0 0 0.125"/><material name="lightblue"/></visual>
      <collision><geometry><cylinder radius="0.04" length="0.25"/></geometry><origin rpy="0 1.57 0" xyz="0 0 0.125"/></collision>
      <inertial> <mass value="0.5"/> <inertia ixx="0.05" ixy="0" ixz="0" iyy="0.05" iyz="0" izz="0.05"/> </inertial>
  </link>
  <joint name="elbow_l" type="revolute">
      <parent link="upper_arm_l"/><child link="lower_arm_l"/><origin xyz="0 0 0.3"/><axis xyz="0 1 0"/><limit effort="100" lower="0" upper="2.8" velocity="10"/>
  </joint>

  <!-- Legs -->
  <link name="upper_leg_r">
    <visual><geometry><cylinder radius="0.07" length="0.4"/></geometry><origin rpy="0 1.57 0" xyz="0 0 0.2"/><material name="blue"/></visual>
    <collision><geometry><cylinder radius="0.07" length="0.4"/></geometry><origin rpy="0 1.57 0" xyz="0 0 0.2"/></collision>
    <inertial> <mass value="5"/> <inertia ixx="0.5" ixy="0" ixz="0" iyy="0.5" iyz="0" izz="0.5"/> </inertial>
  </link>
  <joint name="hip_r" type="revolute">
    <parent link="torso"/><child link="upper_leg_r"/><origin xyz="0 -0.1 -0.25"/><axis xyz="0 1 0"/><limit effort="100" lower="-1.57" upper="1.57" velocity="10"/>
  </joint>

  <link name="lower_leg_r">
    <visual><geometry><cylinder radius="0.06" length="0.4"/></geometry><origin rpy="0 1.57 0" xyz="0 0 0.2"/><material name="lightblue"/></visual>
    <collision><geometry><cylinder radius="0.06" length="0.4"/></geometry><origin rpy="0 1.57 0" xyz="0 0 0.2"/></collision>
    <inertial> <mass value="3"/> <inertia ixx="0.3" ixy="0" ixz="0" iyy="0.3" iyz="0" izz="0.3"/> </inertial>
  </link>
  <joint name="knee_r" type="revolute">
    <parent link="upper_leg_r"/><child link="lower_leg_r"/><origin xyz="0 0 0.4"/><axis xyz="0 1 0"/><limit effort="100" lower="0" upper="2.8" velocity="10"/>
  </joint>

  <link name="upper_leg_l">
    <visual><geometry><cylinder radius="0.07" length="0.4"/></geometry><origin rpy="0 1.57 0" xyz="0 0 0.2"/><material name="blue"/></visual>
    <collision><geometry><cylinder radius="0.07" length="0.4"/></geometry><origin rpy="0 1.57 0" xyz="0 0 0.2"/></collision>
    <inertial> <mass value="5"/> <inertia ixx="0.5" ixy="0" ixz="0" iyy="0.5" iyz="0" izz="0.5"/> </inertial>
  </link>
  <joint name="hip_l" type="revolute">
    <parent link="torso"/><child link="upper_leg_l"/><origin xyz="0 0.1 -0.25"/><axis xyz="0 1 0"/><limit effort="100" lower="-1.57" upper="1.57" velocity="10"/>
  </joint>

  <link name="lower_leg_l">
    <visual><geometry><cylinder radius="0.06" length="0.4"/></geometry><origin rpy="0 1.57 0" xyz="0 0 0.2"/><material name="lightblue"/></visual>
    <collision><geometry><cylinder radius="0.06" length="0.4"/></geometry><origin rpy="0 1.57 0" xyz="0 0 0.2"/></collision>
    <inertial> <mass value="3"/> <inertia ixx="0.3" ixy="0" ixz="0" iyy="0.3" iyz="0" izz="0.3"/> </inertial>
  </link>
  <joint name="knee_l" type="revolute">
    <parent link="upper_leg_l"/><child link="lower_leg_l"/><origin xyz="0 0 0.4"/><axis xyz="0 1 0"/><limit effort="100" lower="0" upper="2.8" velocity="10"/>
  </joint>

  <!-- Spine -->
  <link name="neck">
    <visual><geometry><cylinder radius="0.04" length="0.15"/></geometry><origin rpy="0 1.57 0" xyz="0 0 0.075"/><material name="lightblue"/></visual>
    <collision><geometry><cylinder radius="0.04" length="0.15"/></geometry><origin rpy="0 1.57 0" xyz="0 0 0.075"/></collision>
    <inertial> <mass value="0.5"/> <inertia ixx="0.05" ixy="0" ixz="0" iyy="0.05" iyz="0" izz="0.05"/> </inertial>
  </link>
  <joint name="neck_joint" type="revolute">
    <parent link="torso"/><child link="neck"/><origin xyz="0 0 0.5"/><axis xyz="0 1 0"/><limit effort="100" lower="-0.78" upper="0.78" velocity="10"/>
  </link>

  <!-- Materials -->
  <material name="blue"><color rgba="0 0 0.8 1"/></material>
  <material name="lightblue"><color rgba="0.5 0.5 1 1"/></material>

</robot>
